[2022-09-23 16:13:18,103] {taskinstance.py:1032} INFO - Dependencies all met for <TaskInstance: kag_to_gcs_dag.local_to_gcs_task manual__2022-09-23T16:07:26.134082+00:00 [queued]>
[2022-09-23 16:13:18,112] {taskinstance.py:1032} INFO - Dependencies all met for <TaskInstance: kag_to_gcs_dag.local_to_gcs_task manual__2022-09-23T16:07:26.134082+00:00 [queued]>
[2022-09-23 16:13:18,113] {taskinstance.py:1238} INFO - 
--------------------------------------------------------------------------------
[2022-09-23 16:13:18,113] {taskinstance.py:1239} INFO - Starting attempt 3 of 4
[2022-09-23 16:13:18,113] {taskinstance.py:1240} INFO - 
--------------------------------------------------------------------------------
[2022-09-23 16:13:18,124] {taskinstance.py:1259} INFO - Executing <Task(PythonOperator): local_to_gcs_task> on 2022-09-23 16:07:26.134082+00:00
[2022-09-23 16:13:18,131] {standard_task_runner.py:52} INFO - Started process 6162 to run task
[2022-09-23 16:13:18,134] {standard_task_runner.py:76} INFO - Running: ['***', 'tasks', 'run', 'kag_to_gcs_dag', 'local_to_gcs_task', 'manual__2022-09-23T16:07:26.134082+00:00', '--job-id', '15', '--raw', '--subdir', 'DAGS_FOLDER/kag_to_gcs_dag.py', '--cfg-path', '/tmp/tmp_iegx7pc', '--error-file', '/tmp/tmpxqq8stwt']
[2022-09-23 16:13:18,135] {standard_task_runner.py:77} INFO - Job 15: Subtask local_to_gcs_task
[2022-09-23 16:13:18,185] {logging_mixin.py:109} INFO - Running <TaskInstance: kag_to_gcs_dag.local_to_gcs_task manual__2022-09-23T16:07:26.134082+00:00 [running]> on host 31708a4d5ab1
[2022-09-23 16:13:18,241] {taskinstance.py:1426} INFO - Exporting the following env vars:
AIRFLOW_CTX_DAG_OWNER=***
AIRFLOW_CTX_DAG_ID=kag_to_gcs_dag
AIRFLOW_CTX_TASK_ID=local_to_gcs_task
AIRFLOW_CTX_EXECUTION_DATE=2022-09-23T16:07:26.134082+00:00
AIRFLOW_CTX_DAG_RUN_ID=manual__2022-09-23T16:07:26.134082+00:00
[2022-09-23 16:13:20,113] {taskinstance.py:1700} ERROR - Task failed with exception
Traceback (most recent call last):
  File "/opt/airflow/dags/kag_to_gcs_dag.py", line 52, in upload_to_gcs
    print(f"downloading {file_result.files[i]}")
TypeError: list indices must be integers or slices, not File

During handling of the above exception, another exception occurred:

Traceback (most recent call last):
  File "/home/airflow/.local/lib/python3.7/site-packages/airflow/models/taskinstance.py", line 1329, in _run_raw_task
    self._execute_task_with_callbacks(context)
  File "/home/airflow/.local/lib/python3.7/site-packages/airflow/models/taskinstance.py", line 1455, in _execute_task_with_callbacks
    result = self._execute_task(context, self.task)
  File "/home/airflow/.local/lib/python3.7/site-packages/airflow/models/taskinstance.py", line 1511, in _execute_task
    result = execute_callable(context=context)
  File "/home/airflow/.local/lib/python3.7/site-packages/airflow/operators/python.py", line 174, in execute
    return_value = self.execute_callable()
  File "/home/airflow/.local/lib/python3.7/site-packages/airflow/operators/python.py", line 185, in execute_callable
    return self.python_callable(*self.op_args, **self.op_kwargs)
  File "/opt/airflow/dags/kag_to_gcs_dag.py", line 58, in upload_to_gcs
    print(f"{file_result.files[i]} could not be found")
TypeError: list indices must be integers or slices, not File
[2022-09-23 16:13:20,127] {taskinstance.py:1277} INFO - Marking task as UP_FOR_RETRY. dag_id=kag_to_gcs_dag, task_id=local_to_gcs_task, execution_date=20220923T160726, start_date=20220923T161318, end_date=20220923T161320
[2022-09-23 16:13:20,139] {standard_task_runner.py:92} ERROR - Failed to execute job 15 for task local_to_gcs_task
Traceback (most recent call last):
  File "/opt/airflow/dags/kag_to_gcs_dag.py", line 52, in upload_to_gcs
    print(f"downloading {file_result.files[i]}")
TypeError: list indices must be integers or slices, not File

During handling of the above exception, another exception occurred:

Traceback (most recent call last):
  File "/home/airflow/.local/lib/python3.7/site-packages/airflow/task/task_runner/standard_task_runner.py", line 85, in _start_by_fork
    args.func(args, dag=self.dag)
  File "/home/airflow/.local/lib/python3.7/site-packages/airflow/cli/cli_parser.py", line 48, in command
    return func(*args, **kwargs)
  File "/home/airflow/.local/lib/python3.7/site-packages/airflow/utils/cli.py", line 92, in wrapper
    return f(*args, **kwargs)
  File "/home/airflow/.local/lib/python3.7/site-packages/airflow/cli/commands/task_command.py", line 298, in task_run
    _run_task_by_selected_method(args, dag, ti)
  File "/home/airflow/.local/lib/python3.7/site-packages/airflow/cli/commands/task_command.py", line 107, in _run_task_by_selected_method
    _run_raw_task(args, ti)
  File "/home/airflow/.local/lib/python3.7/site-packages/airflow/cli/commands/task_command.py", line 184, in _run_raw_task
    error_file=args.error_file,
  File "/home/airflow/.local/lib/python3.7/site-packages/airflow/utils/session.py", line 70, in wrapper
    return func(*args, session=session, **kwargs)
  File "/home/airflow/.local/lib/python3.7/site-packages/airflow/models/taskinstance.py", line 1329, in _run_raw_task
    self._execute_task_with_callbacks(context)
  File "/home/airflow/.local/lib/python3.7/site-packages/airflow/models/taskinstance.py", line 1455, in _execute_task_with_callbacks
    result = self._execute_task(context, self.task)
  File "/home/airflow/.local/lib/python3.7/site-packages/airflow/models/taskinstance.py", line 1511, in _execute_task
    result = execute_callable(context=context)
  File "/home/airflow/.local/lib/python3.7/site-packages/airflow/operators/python.py", line 174, in execute
    return_value = self.execute_callable()
  File "/home/airflow/.local/lib/python3.7/site-packages/airflow/operators/python.py", line 185, in execute_callable
    return self.python_callable(*self.op_args, **self.op_kwargs)
  File "/opt/airflow/dags/kag_to_gcs_dag.py", line 58, in upload_to_gcs
    print(f"{file_result.files[i]} could not be found")
TypeError: list indices must be integers or slices, not File
[2022-09-23 16:13:20,154] {local_task_job.py:154} INFO - Task exited with return code 1
[2022-09-23 16:13:20,182] {local_task_job.py:264} INFO - 0 downstream tasks scheduled from follow-on schedule check
